Workbook

Sheet Результати
A1: Назва Установи / Середньорічні показники | B1: Напрям | C1: Установа | D1: Підпорядкування | E1: Регіон | F1: ЄДРПОУ | G1: Область | H1: Сума вагових коєфіцієнтів, I* | I1: Середній бал Експерта | J1: Зважена сумарна оцінка (80/20) | K1: Нормована зважена сумарна оцінка | L1: Регіональний коєфіцієнт | M1: Коєфіцієнт руйнувань | N1: Попередня атестаційна оцінка | O1: Група
A2: Національний юридичний університет імені Ярослава Мудрого | B2: Суспільний | C2: Заклад вищої освіти | D2: Міністерство освіти і науки України | E2: Донецька, Запорізька, Луганська, Миколаївська, Сумська, Харківська, Херсонська область | F2: 02071139 | G2: Харківська область | H2: 36.5469 | I2: 6.1 | J2: 30.4575 | K2: 83.7868 | L2: 1.1 | M2: 1.298 | N2: 100 | O2: А
A3: Сумський державний університет | B3: Суспільний | C3: Заклад вищої освіти | D3: Міністерство освіти і науки України | E3: Донецька, Запорізька, Луганська, Миколаївська, Сумська, Харківська, Херсонська область | F3: 05408289 | G3: Сумська область | H3: 43.689 | I3: 7 | J3: 36.3512 | K3: 100 | L3: 1.1 | M3: 1 | N3: 100 | O3: А
A4: Національний університет біоресурсів і природокористування України | B4: Суспільний | C4: Заклад вищої освіти | D4: Міністерство освіти і науки України | E4: інші області | F4: 00493706 | G4: Київ | H4: 36.794 | I4: 6.1333 | J4: 30.6619 | K4: 84.3491 | L4: 1 | M4: 1 | N4: 84 | O4: А
A5: Харківський національний університет імені В.Н. Каразіна | B5: Суспільний | C5: Заклад вищої освіти | D5: Міністерство освіти і науки України | E5: Донецька, Запорізька, Луганська, Миколаївська, Сумська, Харківська, Херсонська область | F5: 02071205 | G5: Харківська область | H5: 30.0178 | I5: 5.9667 | J5: 25.2076 | K5: 69.3446 | L5: 1.1 | M5: 1.06 | N5: 81 | O5: А
A6: Київський національний університет імені Тараса Шевченка | B6: Суспільний | C6: Заклад вищої освіти | D6: Міністерство освіти і науки України | E6: інші області | F6: 02070944 | G6: Київ | H6: 33.9394 | I6: 6.5187 | J6: 28.4553 | K6: 78.2788 | L6: 1 | M6: 1.028 | N6: 80 | O6: А
A7: Національний університет «Києво-Могилянська академія» | B7: Суспільний | C7: Заклад вищої освіти | D7: Міністерство освіти і науки України | E7: інші області | F7: 16459396 | G7: Київ | H7: 32.7942 | I7: 7.4333 | J7: 27.722 | K7: 76.2616 | L7: 1 | M7: 1 | N7: 76 | O7: А
A8: Харківський національний економічний університет імені Семена Кузнеця | B8: Суспільний | C8: Заклад вищої освіти | D8: Міністерство освіти і науки України | E8: Донецька, Запорізька, Луганська, Миколаївська, Сумська, Харківська, Херсонська область | F8: 02071211 | G8: Харківська область | H8: 30.101 | I8: 5.3667 | J8: 25.1541 | K8: 69.1974 | L8: 1.1 | M8: 1 | N8: 76 | O8: А
A9: Донецький національний університет імені Василя Стуса | B9: Суспільний | C9: Заклад вищої освіти | D9: Міністерство освіти і науки України | E9: тимчасово переміщений НУ / ЗВО, що утримує матеріально-технічну базу за своєю юридичною адресою | F9: 02070803 | G9: Донецька область | H9: 28.7447 | I9: 3.7 | J9: 23.7358 | K9: 65.2958 | L9: 1.15 | M9: 1 | N9: 75 | O9: А
A10: Одеський національний економічний університет | B10: Суспільний | C10: Заклад вищої освіти | D10: Міністерство освіти і науки України | E10: Дніпропетровська, Одеська, Чернігівська область | F10: 02071079 | G10: Одеська область | H10: 28.4164 | I10: 4.2667 | J10: 23.5865 | K10: 64.8851 | L10: 1.05 | M10: 1.068 | N10: 73 | O10: Б
A11: Волинський національний університет імені Лесі Українки | B11: Суспільний | C11: Заклад вищої освіти | D11: Міністерство освіти і науки України | E11: інші області | F11: 02125102 | G11: Волинська область | H11: 29.9882 | I11: 4.4667 | J11: 24.8839 | K11: 68.4541 | L11: 1 | M11: 1 | N11: 68 | O11: Б
A12: Національний університет «Львівська політехніка» | B12: Суспільний | C12: Заклад вищої освіти | D12: Міністерство освіти і науки України | E12: інші області | F12: 02071010 | G12: Львівська область | H12: 29.16 | I12: 5.9 | J12: 24.508 | K12: 67.4201 | L12: 1 | M12: 1 | N12: 67 | O12: Б
A13: Державний університет "Житомирська Політехніка": | B13: Суспільний | C13: Заклад вищої освіти | D13: Міністерство освіти і науки України | E13: інші області | F13: 05407870 | G13: Житомирська область | H13: 28.9646 | I13: 4.4 | J13: 24.0517 | K13: 66.1648 | L13: 1 | M13: 1 | N13: 66 | O13: Б
... A229: Інститут тваринництва степових районів імені М.Ф. Іванова "Асканія-Нова" - Національний науковий селекційно-генетичний центр вівчарства | B229: Аграрно-ветеринарний | C229: Наукова установа | D229: Національна академія аграрних наук України | E229: тимчасово переміщений НУ / ЗВО, що утримує матеріально-технічну базу за своєю юридичною адресою | F229: 00497265 | G229: Херсонська область | H229: 6.3266 | I229: 4.875 | J229: 6.0363 | K229: 23.1213 | L229: 1.15 | M229: 1 | N229: 27 | O229: В
A230: - | B230: - | C230: - | D230: - | E230: - | F230: - | G230: Крим | H230: - | I230: - | J230: - | K230: - | L230: - | M230: - | N230: - | O230: -
A231: - | B231: - | C231: - | D231: - | E231: - | F231: - | G231: Севастополь | H231: - | I231: - | J231: - | K231: - | L231: - | M231: - | N231: - | O231: -
A232: - | B232: - | C232: - | D232: - | E232: - | F232: - | G232: Автономна Республіка Крим | H232: - | I232: - | J232: - | K232: - | L232: - | M232: - | N232: - | O232: -
A233: Київський національний університет імені Тараса Шевченка | B233: Природничо-математичний | C233: Заклад вищої освіти | D233: Міністерство освіти і науки України | E233: інші області | F233: 02070944 | G233: Київ | H233: 45.5843 | I233: 7.8 | J233: 38.0274 | K233: 100 | L233: 1 | M233: 1.034 | N233: 100 | O233: А
A234: Харківський національний університет імені В.Н. Каразіна | B234: Природничо-математичний | C234: Заклад вищої освіти | D234: Міністерство освіти і науки України | E234: Донецька, Запорізька, Луганська, Миколаївська, Сумська, Харківська, Херсонська область | F234: 02071205 | G234: Харківська область | H234: 40.6713 | I234: 7.5667 | J234: 34.0504 | K234: 89.5418 | L234: 1.1 | M234: 1.092 | N234: 100 | O234: А
A235: Національний університет «Львівська політехніка» | B235: Природничо-математичний | C235: Заклад вищої освіти | D235: Міністерство освіти і науки України | E235: інші області | F235: 02071010 | G235: Львівська область | H235: 44.1836 | I235: 7.4443 | J235: 36.8357 | K235: 96.8662 | L235: 1 | M235: 1 | N235: 97 | O235: А
A236: Сумський державний університет | B236: Природничо-математичний | C236: Заклад вищої освіти | D236: Міністерство освіти і науки України | E236: Донецька, Запорізька, Луганська, Миколаївська, Сумська, Харківська, Херсонська область | F236: 05408289 | G236: Сумська область | H236: 38.5483 | I236: 6.8667 | J236: 32.212 | K236: 84.7073 | L236: 1.1 | M236: 1.004 | N236: 94 | O236: А
A237: Національний технічний університет "Харківський політехнічний інститут" | B237: Природничо-математичний | C237: Заклад вищої освіти | D237: Міністерство освіти і науки України | E237: Донецька, Запорізька, Луганська, Миколаївська, Сумська, Харківська, Херсонська область | F237: 02071180 | G237: Харківська область | H237: 37.187 | I237: 7.0667 | J237: 31.1629 | K237: 81.9485 | L237: 1.1 | M237: 1.028 | N237: 93 | O237: А
A238: Державний вищий навчальний заклад "Ужгородський національний університет" | B238: Природничо-математичний | C238: Заклад вищої освіти | D238: Міністерство освіти і науки України | E238: інші області | F238: 02070832 | G238: Закарпатська область | H238: 42.2071 | I238: 6.0333 | J238: 34.9723 | K238: 91.9661 | L238: 1 | M238: 1 | N238: 92 | O238: А
A239: Харківський національний університет міського господарства імені О.М.Бекетова | B239: Природничо-математичний | C239: Заклад вищої освіти | D239: Міністерство освіти і науки України | E239: Донецька, Запорізька, Луганська, Миколаївська, Сумська, Харківська, Херсонська область | F239: 02071151 | G239: Харківська область | H239: 34.5673 | I239: 6 | J239: 28.8538 | K239: 75.8763 | L239: 1.1 | M239: 1.023 | N239: 85 | O239: А
A240: Львівський національний університет імені Івана Франка | B240: Природничо-математичний | C240: Заклад вищої освіти | D240: Міністерство освіти і науки України | E240: інші області | F240: 02070987 | G240: Львівська область | H240: 35.7692 | I240: 6.8 | J240: 29.9754 | K240: 78.8258 | L240: 1 | M240: 1 | N240: 79 | O240: А
A241: Дніпровський національний університет імені Олеся Гончара | B241: Природничо-математичний | C241: Заклад вищої освіти | D241: Міністерство освіти і науки України | E241: Дніпропетровська, Одеська, Чернігівська область | F241: 02066747 | G241: Дніпропетровська область | H241: 33.8829 | I241: 5.5333 | J241: 28.213 | K241: 74.1912 | L241: 1.05 | M241: 1 | N241: 78 | O241: А
A242: Прикарпатський національний університет імені Василя Стефаника | B242: Природничо-математичний | C242: Заклад вищої освіти | D242: Міністерство освіти і науки України | E242: інші області | F242: 02125266 | G242: Івано-Франківська область | H242: 35.3557 | I242: 5.5713 | J242: 29.3988 | K242: 77.3095 | L242: 1 | M242: 1 | N242: 77 | O242: А
A243: Запорізький національний університет | B243: Природничо-математичний | C243: Заклад вищої освіти | D243: Міністерство освіти і науки України | E243: Донецька, Запорізька, Луганська, Миколаївська, Сумська, Харківська, Херсонська область | F243: 02125243 | G243: Запорізька область | H243: 25.8006 | I243: 5.7 | J243: 21.7805 | K243: 57.2758 | L243: 1.1 | M243: 1.157 | N243: 73 | O243: Б
A244: Національний технічний університет «Дніпровська політехніка» | B244: Природничо-математичний | C244: Заклад вищої освіти | D244: Міністерство освіти і науки України | E244: Дніпропетровська, Одеська, Чернігівська область | F244: 02070743 | G244: Дніпропетровська область | H244: 29.8018 | I244: 6.5557 | J244: 25.1526 | K244: 66.1434 | L244: 1.05 | M244: 1 | N244: 69 | O244: Б
... A674: Державна установа "Інститут проблем ендокринної патології імені В.Я. Данилевського Національної академії наук України" | B674: Біомедичний | C674: Наукова установа | D674: Національна академія медичних наук України | E674: Донецька, Запорізька, Луганська, Миколаївська, Сумська, Харківська, Херсонська область | F674: 02012131 | G674: Харківська область | H674: 16.6615 | I674: 7.5667 | J674: 14.8425 | K674: 44.6765 | L674: 1.1 | M674: 1.2 | N674: 59 | O674: Б

Sheet ДО результатів 
E1: Київська муніципальна академія музики ім. Р.М. Глієра | F1: Гуманітарно-мистецький | G1: Заклад вищої освіти | H1: Київська міська державна адміністрація | I1: інші області | J1: 02214923 | K1: Київ | L1: 8.9835 | M1: 7.4583 | N1: 8.6785 | O1: 29.1823 | P1: 1 | Q1: 1 | R1: 29 | S1: В
E2: Український науково-дослідний інститут архівної справи та документознавства | F2: Гуманітарно-мистецький | G2: Наукова установа | H2: Державна архівна служба України | I2: інші області | J2: 22892594 | K2: Київ | L2: 11.7143 | M2: 6.6667 | N2: 10.7048 | O2: 62.4208 | P2: 1 | Q2: 1 | R2: 62 | S2: Б
E3: Державна наукова установа "Центр інноваційних технологій охорони здоров'я" Державного управління справами | F3: Біомедичний | G3: Наукова установа | H3: Державне управління справами | I3: інші області | J3: 45633922 | K3: Київ | L3: 13.3196 | M3: 5.0667 | N3: 11.669 | O3: 35.1241 | P3: 1 | Q3: 1 | R3: 35 | S3: В
E4: Державна наукова установа "Книжкова палата України імені Івана Федорова" | F4: Гуманітарно-мистецький | G4: Наукова установа | H4: Державний комітет телебачення і радіомовлення України | I4: інші області | J4: 02473085 | K4: Київ | L4: 2.157 | M4: 6.2 | N4: 2.9656 | O4: 17.2927 | P4: 1 | Q4: 1 | R4: 17 | S4: Г
E5: Львівська національна академія мистецтв | F5: Гуманітарно-мистецький | G5: Заклад вищої освіти | H5: Міністерство культури та стратегічних комунікацій України | I5: інші області | J5: 02071027 | K5: Львівська область | L5: 17.0741 | M5: 7.0333 | N5: 15.0659 | O5: 50.6606 | P5: 1 | Q5: 1 | R5: 51 | S5: Б
E6: НАЦІОНАЛЬНА АКАДЕМІЯ ОБРАЗОТВОРЧОГО МИСТЕЦТВА І АРХІТЕКТУРИ | F6: Гуманітарно-мистецький | G6: Заклад вищої освіти | H6: Міністерство культури та стратегічних комунікацій України | I6: інші області | J6: 02214165 | K6: Київ | L6: 2.7144 | M6: 5.3667 | N6: 3.2449 | O6: 10.9113 | P6: 1 | Q6: 1 | R6: 11 | S6: Г
E7: Державна наукова установа "Енциклопедичне видавництво" | F7: Гуманітарно-мистецький | G7: Наукова установа | H7: Міністерство культури та стратегічних комунікацій України | I7: інші області | J7: 38780038 | K7: Київ | L7: 8.5617 | M7: 6.8333 | N7: 8.216 | O7: 47.9084 | P7: 1 | Q7: 1 | R7: 48 | S7: В
E8: УКРАЇНСЬКА ВІЙСЬКОВО-МЕДИЧНА АКАДЕМІЯ | F8: Біомедичний | G8: Заклад вищої освіти | H8: Міністерство оборони України | I8: інші області | J8: 22998499 | K8: Київ | L8: 12.8757 | M8: 6 | N8: 11.5006 | O8: 33.1635 | P8: 1 | Q8: 1 | R8: 33 | S8: В
E9: Київський національний економічний університет імені Вадима Гетьмана | F9: Гуманітарно-мистецький | G9: Заклад вищої освіти | H9: Міністерство освіти і науки України | I9: інші області | J9: 02070884 | K9: Київ | L9: 13.2089 | M9: 1.6 | N9: 11.8005 | O9: 39.6804 | P9: 1 | Q9: 1 | R9: 40 | S9: В
E10: Національний університет «Одеська юридична академія» | F10: Гуманітарно-мистецький | G10: Заклад вищої освіти | H10: Міністерство освіти і науки України | I10: Дніпропетровська, Одеська, Чернігівська область | J10: 20933314 | K10: Одеська область | L10: 4.0225 | M10: 3.75 | N10: 3.968 | O10: 13.3428 | P10: 1.05 | Q10: 1 | R10: 14 | S10: Г
E11: Національний університет «Львівська політехніка» | F11: Гуманітарно-мистецький | G11: Заклад вищої освіти | H11: Міністерство освіти і науки України | I11: інші області | J11: 02071010 | K11: Львівська область | L11: 32.7215 | M11: 7.2667 | N11: 27.6305 | O11: 92.9103 | P11: 1 | Q11: 1 | R11: 93 | S11: А
E12: ДВНЗ «Донбаський державний педагогічний університет» | F12: Гуманітарно-мистецький | G12: Заклад вищої освіти | H12: Міністерство освіти і науки України | I12: тимчасово переміщений НУ / ЗВО, що утримує матеріально-технічну базу за своєю юридичною адресою | J12: 38177113 | K12: Донецька область | L12: 15.3273 | M12: 4.2025 | N12: 13.3418 | O12: 44.8631 | P12: 1.15 | Q12: 1 | R12: 52 | S12: Б
... E160: Державна установа "Інститут проблем ендокринної патології імені В.Я. Данилевського Національної академії наук України" | F160: Біомедичний | G160: Наукова установа | H160: Національна академія медичних наук України | I160: Донецька, Запорізька, Луганська, Миколаївська, Сумська, Харківська, Херсонська область | J160: 02012131 | K160: Харківська область | L160: 16.6615 | M160: 7.5667 | N160: 14.8425 | O160: 44.6765 | P160: 1.1 | Q160: 1.2 | R160: 59 | S160: Б

Sheet Аркуш22
A1: Назва Установи / Середньорічні показники | B1: Напрям | D1: Установа | E1: Підпорядкування | F1: Регіон | G1: ЄДРПОУ | H1: Область | I1: Сума вагових коєфіцієнтів, I* | J1: Середній бал Експерта | K1: Зважена сумарна оцінка (80/20) | L1: Нормована зважена сумарна оцінка | M1: Регіональний коєфіцієнт | N1: Коєфіцієнт руйнувань | O1: Попередня атестаційна оцінка | P1: Група
A2: Національний юридичний університет імені Ярослава Мудрого | B2: Суспільний | D2: Заклад вищої освіти | E2: Міністерство освіти і науки України | F2: Донецька, Запорізька, Луганська, Миколаївська, Сумська, Харківська, Херсонська область | G2: 02071139 | H2: Харківська область | I2: 36.5469 | J2: 6.1 | K2: 30.4575 | L2: 83.7868 | M2: 1.1 | N2: 1.298 | O2: 100 | P2: А
A3: Сумський державний університет | B3: Суспільний | D3: Заклад вищої освіти | E3: Міністерство освіти і науки України | F3: Донецька, Запорізька, Луганська, Миколаївська, Сумська, Харківська, Херсонська область | G3: 05408289 | H3: Сумська область | I3: 43.689 | J3: 7 | K3: 36.3512 | L3: 100 | M3: 1.1 | N3: 1 | O3: 100 | P3: А
A4: Національний університет біоресурсів і природокористування України | B4: Суспільний | D4: Заклад вищої освіти | E4: Міністерство освіти і науки України | F4: інші області | G4: 00493706 | H4: Київ | I4: 36.794 | J4: 6.1333 | K4: 30.6619 | L4: 84.3491 | M4: 1 | N4: 1 | O4: 84 | P4: А
A5: Харківський національний університет імені В.Н. Каразіна | B5: Суспільний | D5: Заклад вищої освіти | E5: Міністерство освіти і науки України | F5: Донецька, Запорізька, Луганська, Миколаївська, Сумська, Харківська, Херсонська область | G5: 02071205 | H5: Харківська область | I5: 30.0178 | J5: 5.9667 | K5: 25.2076 | L5: 69.3446 | M5: 1.1 | N5: 1.06 | O5: 81 | P5: А
A6: Київський національний університет імені Тараса Шевченка | B6: Суспільний | D6: Заклад вищої освіти | E6: Міністерство освіти і науки України | F6: інші області | G6: 02070944 | H6: Київ | I6: 33.9394 | J6: 6.5187 | K6: 28.4553 | L6: 78.2788 | M6: 1 | N6: 1.028 | O6: 80 | P6: А
A7: Національний університет «Києво-Могилянська академія» | B7: Суспільний | D7: Заклад вищої освіти | E7: Міністерство освіти і науки України | F7: інші області | G7: 16459396 | H7: Київ | I7: 32.7942 | J7: 7.4333 | K7: 27.722 | L7: 76.2616 | M7: 1 | N7: 1 | O7: 76 | P7: А
A8: Харківський національний економічний університет імені Семена Кузнеця | B8: Суспільний | D8: Заклад вищої освіти | E8: Міністерство освіти і науки України | F8: Донецька, Запорізька, Луганська, Миколаївська, Сумська, Харківська, Херсонська область | G8: 02071211 | H8: Харківська область | I8: 30.101 | J8: 5.3667 | K8: 25.1541 | L8: 69.1974 | M8: 1.1 | N8: 1 | O8: 76 | P8: А
A9: Донецький національний університет імені Василя Стуса | B9: Суспільний | D9: Заклад вищої освіти | E9: Міністерство освіти і науки України | F9: тимчасово переміщений НУ / ЗВО, що утримує матеріально-технічну базу за своєю юридичною адресою | G9: 02070803 | H9: Донецька область | I9: 28.7447 | J9: 3.7 | K9: 23.7358 | L9: 65.2958 | M9: 1.15 | N9: 1 | O9: 75 | P9: А
A10: Одеський національний економічний університет | B10: Суспільний | D10: Заклад вищої освіти | E10: Міністерство освіти і науки України | F10: Дніпропетровська, Одеська, Чернігівська область | G10: 02071079 | H10: Одеська область | I10: 28.4164 | J10: 4.2667 | K10: 23.5865 | L10: 64.8851 | M10: 1.05 | N10: 1.068 | O10: 73 | P10: Б
A11: Волинський національний університет імені Лесі Українки | B11: Суспільний | D11: Заклад вищої освіти | E11: Міністерство освіти і науки України | F11: інші області | G11: 02125102 | H11: Волинська область | I11: 29.9882 | J11: 4.4667 | K11: 24.8839 | L11: 68.4541 | M11: 1 | N11: 1 | O11: 68 | P11: Б
A12: Національний університет «Львівська політехніка» | B12: Суспільний | D12: Заклад вищої освіти | E12: Міністерство освіти і науки України | F12: інші області | G12: 02071010 | H12: Львівська область | I12: 29.16 | J12: 5.9 | K12: 24.508 | L12: 67.4201 | M12: 1 | N12: 1 | O12: 67 | P12: Б
A13: Державний університет "Житомирська Політехніка": | B13: Суспільний | D13: Заклад вищої освіти | E13: Міністерство освіти і науки України | F13: інші області | G13: 05407870 | H13: Житомирська область | I13: 28.9646 | J13: 4.4 | K13: 24.0517 | L13: 66.1648 | M13: 1 | N13: 1 | O13: 66 | P13: Б
... A671: Державна установа "Інститут проблем ендокринної патології імені В.Я. Данилевського Національної академії наук України" | B671: Біомедичний | D671: Наукова установа | E671: Національна академія медичних наук України | F671: Донецька, Запорізька, Луганська, Миколаївська, Сумська, Харківська, Херсонська область | G671: 02012131 | H671: Харківська область | I671: 16.6615 | J671: 7.5667 | K671: 14.8425 | L671: 44.6765 | M671: 1.1 | N671: 1.2 | O671: 59 | P671: Б

Sheet Аркуш21
A1: Відповідальні особи вказаної установи | B1: Науковий напрям * Рівень 0 | C1: Коефіцієнти Крі
A2: Установа для демонстраціїБіомедичний | B2: Біомедичний | C2: 1.152
A3: Національний університет «Львівська політехніка»Природничо-математичний | B3: Природничо-математичний | C3: 1
A4: Бердянський державний педагогічний університетПриродничо-математичний | B4: Природничо-математичний | C4: 1
A5: Біосферний заповідник "Асканія-Нова" імені Ф.Е. Фальц-Фейна Національної академії аграрних наук УкраїниПриродничо-математичний | B5: Природничо-математичний | C5: 1
A6: Вінницький державний педагогічний університет імені Михайла КоцюбинськогоПриродничо-математичний | B6: Природничо-математичний | C6: 1
A7: Волинський національний університет імені Лесі УкраїнкиПриродничо-математичний | B7: Природничо-математичний | C7: 1
A8: ІНСТИТУТ КІБЕРНЕТИКИ ІМЕНІ В.М.ГЛУШКОВА НАЦІОНАЛЬНОЇ АКАДЕМІЇ НАУК УКРАЇНИІнженерно-технологічний | B8: Інженерно-технологічний | C8: 1
A9: "КИЇВСЬКИЙ ОБЛАСНИЙ НАУКОВО-ВИРОБНИЧИЙ ЦЕНТР СТАНДАРТИЗАЦІЇ,МЕТРОЛОГІЇ ТА СЕРТИФІКАЦІЇ"(ДП КИЇВОБЛСТАНДАРТМЕТРОЛОГІЯ")Інженерно-технологічний | B9: Інженерно-технологічний | C9: 1
A10: Акціонерне товариство "Український науково-дослідний інститут вогнетривів імені А.С. Бережного"Інженерно-технологічний | B10: Інженерно-технологічний | C10: 1
A11: Відділення фізики гірничих процесів Інституту геотехнічної механіки ім. М.С. Полякова НАН УкраїниІнженерно-технологічний | B11: Інженерно-технологічний | C11: 1
A12: Відділення фізико-хімії горючих копалин Інституту фізико-органічної хімії і вуглехімії ім. Л.М. Литвиненка Національної академії наук УкраїниПриродничо-математичний | B12: Природничо-математичний | C12: 1
A13: Вінницький національний аграрний університетІнженерно-технологічний | B13: Інженерно-технологічний | C13: 1
... A444: УКРАЇНСЬКА ВІЙСЬКОВО-МЕДИЧНА АКАДЕМІЯБіомедичний | B444: Біомедичний | C444: 1

Sheet Мадіани
A1: № | B1: Індикатор | C1: Назва індикатору | D1: Тип установи | E1: Напрям | F1: Медіана
A2: 1 | B2: I1 | C2: Захисти доктори філософії | D2: Заклад вищої освіти | E2: Суспільний | F2: 0.037
A3: 2 | B3: I2 | C3: Захисти доктори наук | D3: Заклад вищої освіти | E3: Суспільний | F3: 0.014
A4: 3 | B4: I3 | C4: Кількість молодих вчених | D4: Заклад вищої освіти | E4: Суспільний | F4: 0.259
A5: 4 | B5: I4 | C5: Кількість наукових працівників за основним місцем роботи** | D5: Заклад вищої освіти | E5: Суспільний | F5: 0
A6: 5 | B6: I5 | C6: Показник гендерної рівності | D6: Заклад вищої освіти | E6: Суспільний | F6: 0.064
A7: 6 | B7: I6 | C7: Кількість дослідників із науковими ступенями | D7: Заклад вищої освіти | E7: Суспільний | F7: 0.811
A8: 7 | B8: I7 | C8: Кількість проведених експертиз | D8: Заклад вищої освіти | E8: Суспільний | F8: 0.009
A9: 8 | B9: I8 | C9: Обсяги залучення міжнародного грантового фінансування (Горизонт, НАТО Євратом) | D9: Заклад вищої освіти | E9: Суспільний | F9: 0
A10: 9 | B10: I9 | C10: Обсяги залучення міжнародного грантового фінансування (інші програми) | D10: Заклад вищої освіти | E10: Суспільний | F10: 3.11
A11: 10 | B11: I10 | C11: Обсяги залучення державного грантового фінансування | D11: Заклад вищої освіти | E11: Суспільний | F11: 0
A12: 11 | B12: I11 | C12: Обсяги залучення коштів бізнесу (іноземні замовники) | D12: Заклад вищої освіти | E12: Суспільний | F12: 0
A13: 12 | B13: I12 | C13: Обсяги залучення коштів бізнесу (українські замовники) | D13: Заклад вищої освіти | E13: Суспільний | F13: 0.502
... A149: 148 | B149: I37 | C149: Кількість заявок на інші міжнародні гранти, як переможець | D149: Наукова установа | E149: Аграрно-ветеринарний | F149: 0

Sheet Фінансування установ
A1: Установа | B1: Підпорядкування | C1: Тип установи | D1: Область | E1: Напрям | F1: Призначення фінансування | G1: Сума фінансування
A2: НАЦІОНАЛЬНИЙ НАУКОВИЙ ЦЕНТР «ІНСТИТУТ ҐРУН­ТО­ЗНАВ­СТВА ТА АГРОХІМІЇ ІМЕНІ О. Н. СОКОЛОВСЬКОГО» | B2: Національна академія агрраних наук України | C2: Наукова установа | D2: Харківська область | E2: Аграрно-ветеринарний | F2: На розвиток дослідницької інфраструктури* | G2: 3714510.6
A3: Національний науковий центр "Інститут землеробства Національної академії аграрних наук України" | B3: Національна академія агрраних наук України | C3: Наукова установа | D3: Київська область | E3: Аграрно-ветеринарний | F3: На розвиток дослідницької інфраструктури* | G3: 6049248.7
A4: Національний науковий центр "Інститут експериментальної і клінічної ветеринарної медицини" | B4: Національна академія агрраних наук України | C4: Наукова установа | D4: Харківська область | E4: Аграрно-ветеринарний | F4: На розвиток дослідницької інфраструктури* | G4: 5548217.6
A5: Інститут сільськогосподарської мікробіології та агропромислового виробництва Національної академії аграрних наук України | B5: Національна академія агрраних наук України | C5: Наукова установа | D5: Чернігівська область | E5: Аграрно-ветеринарний | F5: На розвиток дослідницької інфраструктури* | G5: 3140812.3
A6: Інститут сільського господарства Карпатського регіону Національної академії аграрних наук України | B6: Національна академія агрраних наук України | C6: Наукова установа | D6: Львівська область | E6: Аграрно-ветеринарний | F6: На розвиток дослідницької інфраструктури* | G6: 5998093.7
A7: Інститут рослинництва ім. В.Я. Юр'єва Національної академії аграрних наук України | B7: Національна академія агрраних наук України | C7: Наукова установа | D7: Харківська область | E7: Аграрно-ветеринарний | F7: На розвиток дослідницької інфраструктури* | G7: 6845525.8
A8: Інститут олійних культур Національної академії аграрних наук України | B8: Національна академія агрраних наук України | C8: Наукова установа | D8: Запорізька область | E8: Аграрно-ветеринарний | F8: На розвиток дослідницької інфраструктури* | G8: 989867.14
A9: Інститут водних проблем і меліорації Національної академії аграрних наук України | B9: Національна академія агрраних наук України | C9: Наукова установа | D9: Київ | E9: Аграрно-ветеринарний | F9: На розвиток дослідницької інфраструктури* | G9: 3759456
A10: Інститут біоенергетичних культур і цукрових буряків Національної академії аграрних наук України | B10: Національна академія агрраних наук України | C10: Наукова установа | D10: Київська область | E10: Аграрно-ветеринарний | F10: На розвиток дослідницької інфраструктури* | G10: 3558937
A11: Державний науково-дослідний інститут з лабораторної діагностики та ветеринарно-санітарної експертизи | B11: Державна служба України з питань безпечності харчових продуктів та захисту споживачів | C11: Наукова установа | D11: Київ | E11: Аграрно-ветеринарний | F11: На розвиток дослідницької інфраструктури* | G11: 2519796.2
A12: Науково-дослідний центр індустріальних проблем розвитку НАН України | B12: Національна академія наук України | C12: Наукова установа | D12: Київ | E12: Суспільний | F12: На розвиток дослідницької інфраструктури* | G12: 316267.48
A13: ІНСТИТУТ ЦИФРОВІЗАЦІЇ ОСВІТИ НАЦІОНАЛЬНОЇ АКАДЕМІЇ ПЕДАГОГІЧНИХ НАУК УКРАЇНИ | B13: Національна академія педагогічних наук України | C13: Наукова установа | D13: Київ | E13: Суспільний | F13: На розвиток дослідницької інфраструктури* | G13: 287869.17
... A70: Державна наукова установа «Інститут освітньої аналітики» | B70: Міністерство освіти і науки України | C70: Наукова установа | D70: Київ | E70: Суспільний | F70: На стимулювання кращих підрозділів* | G70: 2039273.1

Sheet Фінансування СП
A1: Установа | B1: Підпорядкування | C1: Тип установи | D1: Область | E1: Напрям | F1: Структурний підрозділ | G1: Класиф.оцінка відділу | H1: Частка в атестації установи | I1: Нормування | J1: Розмір доплати | K1: На відділ на рік
A2: Державний науково-дослідний інститут з лабораторної діагностики та ветеринарно-санітарної експертизи | B2: Державна служба України з питань безпечності харчових продуктів та захисту споживачів | C2: Наукова установа | D2: Київ | E2: Аграрно-ветеринарний | F2: Науково-дослідний бактеріологічний відділ | G2: 4.47 | H2: 0.0886 | I2: 50.64 | J2: 0.75 | K2: 585825.26
A3: Державний науково-дослідний інститут з лабораторної діагностики та ветеринарно-санітарної експертизи | B3: Державна служба України з питань безпечності харчових продуктів та захисту споживачів | C3: Наукова установа | D3: Київ | E3: Аграрно-ветеринарний | F3: Науково-дослідний відділ біохімічних та молекулярних досліджень харчових продуктів, кормів та води | G3: 1.53 | H3: 0.0303 | I3: 17.31 | J3: 0.25 | K3: 45947.08
A4: Державний науково-дослідний інститут з лабораторної діагностики та ветеринарно-санітарної експертизи | B4: Державна служба України з питань безпечності харчових продуктів та захисту споживачів | C4: Наукова установа | D4: Київ | E4: Аграрно-ветеринарний | F4: Науково-дослідний відділ епізоотології та інфекційних хвороб | G4: 6.31 | H4: 0.1252 | I4: 71.55 | J4: 0.75 | K4: 356089.87
A5: Державний науково-дослідний інститут з лабораторної діагностики та ветеринарно-санітарної експертизи | B5: Державна служба України з питань безпечності харчових продуктів та захисту споживачів | C5: Наукова установа | D5: Київ | E5: Аграрно-ветеринарний | F5: Науково-дослідний відділ імунологічних досліджень | G5: 5.68 | H5: 0.1127 | I5: 64.41 | J5: 0.75 | K5: 172301.55
A6: Державний науково-дослідний інститут з лабораторної діагностики та ветеринарно-санітарної експертизи | B6: Державна служба України з питань безпечності харчових продуктів та захисту споживачів | C6: Наукова установа | D6: Київ | E6: Аграрно-ветеринарний | F6: Науково-дослідний відділ молекулярно-генетичних досліджень | G6: 4.62 | H6: 0.0916 | I6: 52.37 | J6: 0.75 | K6: 287169.25
A7: Державний науково-дослідний інститут з лабораторної діагностики та ветеринарно-санітарної експертизи | B7: Державна служба України з питань безпечності харчових продуктів та захисту споживачів | C7: Наукова установа | D7: Київ | E7: Аграрно-ветеринарний | F7: Науково-дослідний вірусологічний відділ | G7: 8.82 | H7: 0.175 | I7: 100 | J7: 1 | K7: 382892.33
A8: Державний науково-дослідний інститут з лабораторної діагностики та ветеринарно-санітарної експертизи | B8: Державна служба України з питань безпечності харчових продуктів та захисту споживачів | C8: Наукова установа | D8: Київ | E8: Аграрно-ветеринарний | F8: Науково-дослідний паразитологічний відділ | G8: 6.88 | H8: 0.1365 | I8: 77.99 | J8: 1 | K8: 107209.85
A9: Державний науково-дослідний інститут з лабораторної діагностики та ветеринарно-санітарної експертизи | B9: Державна служба України з питань безпечності харчових продуктів та захисту споживачів | C9: Наукова установа | D9: Київ | E9: Аграрно-ветеринарний | F9: Науково-дослідний патоморфологічний відділ | G9: 5.54 | H9: 0.1098 | I9: 62.76 | J9: 0.75 | K9: 264195.71
A10: Державний науково-дослідний інститут з лабораторної діагностики та ветеринарно-санітарної експертизи | B10: Державна служба України з питань безпечності харчових продуктів та захисту споживачів | C10: Наукова установа | D10: Київ | E10: Аграрно-ветеринарний | F10: Науково-дослідний радіологічний відділ | G10: 1.64 | H10: 0.0325 | I10: 18.55 | J10: 0.25 | K10: 88065.24
A11: Державний науково-дослідний інститут з лабораторної діагностики та ветеринарно-санітарної експертизи | B11: Державна служба України з питань безпечності харчових продуктів та захисту споживачів | C11: Наукова установа | D11: Київ | E11: Аграрно-ветеринарний | F11: Науково-дослідний хіміко-токсикологічний відділ | G11: 4.93 | H11: 0.0978 | I11: 55.9 | J11: 0.75 | K11: 356089.87
A12: Інститут біоенергетичних культур і цукрових буряків Національної академії аграрних наук України | B12: Національна академія агрраних наук України | C12: Наукова установа | D12: Київська область | E12: Аграрно-ветеринарний | F12: Відділ агрохімічних досліджень | G12: 5.12 | H12: 0.0865 | I12: 36.04 | J12: 0.5 | K12: 452730.71
A13: Інститут біоенергетичних культур і цукрових буряків Національної академії аграрних наук України | B13: Національна академія агрраних наук України | C13: Наукова установа | D13: Київська область | E13: Аграрно-ветеринарний | F13: Відділ здоров’я рослин | G13: 8.97 | H13: 0.1513 | I13: 63.09 | J13: 0.75 | K13: 590034.29
... A211: Науково-дослідний центр індустріальних проблем розвитку НАН України | B211: Національна академія наук України | C211: Наукова установа | D211: Київ | E211: Суспільний | F211: Відділ промислової політики та енергетичної безпеки | G211: 20.78 | H211: 0.6983 | I211: 100 | J211: 1 | K211: 1018289.3

Sheet Деталі 3.0
A1: Назва установи / Закладу вищої освіти | B1: Установа | C1: Підпорядкування | D1: Регіон | E1: ЄДРПОУ | F1: Область | G1: Напрям | H1: Класифікаційна оцінка | I1: Експертна оцінка | J1: Зважена сумарна оцінка (80/20) | K1: Нормована зважена сумарна оцінка | L1: Регіональний коєфіцієнт | M1: Коєфіцієнт руйнувань | N1: Атестаційна оцінка | O1: Група | P1: Назва показника | Q1: Показник | R1: Індикатор | S1: Нормований індикатор
A2: НАЦІОНАЛЬНИЙ НАУКОВИЙ ЦЕНТР «ІНСТИТУТ ҐРУН­ТО­ЗНАВ­СТВА ТА АГРОХІМІЇ ІМЕНІ О. Н. СОКОЛОВСЬКОГО» | B2: Наукова установа | C2: Національна академія агрраних наук України | D2: Донецька, Запорізька, Луганська, Миколаївська, Сумська, Харківська, Херсонська область | E2: 00497058 | F2: Харківська область | G2: Аграрно-ветеринарний | H2: 28.372 | I2: 7.1667 | J2: 24.1309 | K2: 92.4304 | L2: 1.1 | M2: 1 | N2: 100 | O2: А | P2: Кількість молодих вчених П6, І3 | Q2: 13.6 | R2: 0.207 | S2: 1
A3: Інститут водних проблем і меліорації Національної академії аграрних наук України | B3: Наукова установа | C3: Національна академія агрраних наук України | D3: інші області | E3: 01018947 | F3: Київ | G3: Аграрно-ветеринарний | H3: 31.0135 | I3: 6.4817 | J3: 26.1071 | K3: 100 | L3: 1 | M3: 1 | N3: 100 | O3: А | P3: Кількість молодих вчених П6, І3 | Q3: 11.2 | R3: 0.137 | S3: 1
A4: Національний науковий центр "Інститут експериментальної і клінічної ветеринарної медицини" | B4: Наукова установа | C4: Національна академія агрраних наук України | D4: Донецька, Запорізька, Луганська, Миколаївська, Сумська, Харківська, Херсонська область | E4: 00497086 | F4: Харківська область | G4: Аграрно-ветеринарний | H4: 27.2397 | I4: 6.8333 | J4: 23.1584 | K4: 88.7054 | L4: 1.1 | M4: 1 | N4: 98 | O4: А | P4: Кількість молодих вчених П6, І3 | Q4: 11.4 | R4: 0.143 | S4: 1
A5: Інститут біоенергетичних культур і цукрових буряків Національної академії аграрних наук України | B5: Наукова установа | C5: Національна академія агрраних наук України | D5: інші області | E5: 00489780 | F5: Київська область | G5: Аграрно-ветеринарний | H5: 27.2374 | I5: 6.8573 | J5: 23.1614 | K5: 88.7169 | L5: 1 | M5: 1 | N5: 89 | O5: А | P5: Кількість молодих вчених П6, І3 | Q5: 5.4 | R5: 0.077 | S5: 0.1833
A6: Державний науково-дослідний інститут з лабораторної діагностики та ветеринарно-санітарної експертизи | B6: Наукова установа | C6: Державна служба України з питань безпечності харчових продуктів та захисту споживачів | D6: інші області | E6: 00699690 | F6: Київ | G6: Аграрно-ветеринарний | H6: 26.8699 | I6: 4.9667 | J6: 22.4893 | K6: 86.1425 | L6: 1 | M6: 1 | N6: 86 | O6: А | P6: Кількість молодих вчених П6, І3 | Q6: 10.6 | R6: 0.21 | S6: 1
A7: Інститут сільського господарства Карпатського регіону Національної академії аграрних наук України | B7: Наукова установа | C7: Національна академія агрраних наук України | D7: інші області | E7: 00496952 | F7: Львівська область | G7: Аграрно-ветеринарний | H7: 26.4891 | I7: 4.7777 | J7: 22.1468 | K7: 84.8306 | L7: 1 | M7: 1 | N7: 85 | O7: А | P7: Кількість молодих вчених П6, І3 | Q7: 8.8 | R7: 0.1 | S7: 0.2381
A8: Інститут рослинництва ім. В.Я. Юр'єва Національної академії аграрних наук України | B8: Наукова установа | C8: Національна академія агрраних наук України | D8: Донецька, Запорізька, Луганська, Миколаївська, Сумська, Харківська, Херсонська область | E8: 00497176 | F8: Харківська область | G8: Аграрно-ветеринарний | H8: 17.0976 | I8: 7.1333 | J8: 15.1047 | K8: 57.8567 | L8: 1.1 | M8: 1.3 | N8: 83 | O8: А | P8: Кількість молодих вчених П6, І3 | Q8: 18.6 | R8: 0.159 | S8: 1
A9: Національний науковий центр "Інститут землеробства Національної академії аграрних наук України" | B9: Наукова установа | C9: Національна академія агрраних наук України | D9: інші області | E9: 00496834 | F9: Київська область | G9: Аграрно-ветеринарний | H9: 24.4597 | I9: 4.8667 | J9: 20.5411 | K9: 78.6801 | L9: 1 | M9: 1 | N9: 79 | O9: А | P9: Кількість молодих вчених П6, І3 | Q9: 36 | R9: 0.237 | S9: 1
A10: Інститут олійних культур Національної академії аграрних наук України | B10: Наукова установа | C10: Національна академія агрраних наук України | D10: Донецька, Запорізька, Луганська, Миколаївська, Сумська, Харківська, Херсонська область | E10: 01296051 | F10: Запорізька область | G10: Аграрно-ветеринарний | H10: 22.3789 | I10: 3.4667 | J10: 18.5965 | K10: 71.2316 | L10: 1.1 | M10: 1 | N10: 78 | O10: А | P10: Кількість молодих вчених П6, І3 | Q10: 3.4 | R10: 0.081 | S10: 0.1929
A11: Інститут сільськогосподарської мікробіології та агропромислового виробництва Національної академії аграрних наук України | B11: Наукова установа | C11: Національна академія агрраних наук України | D11: Дніпропетровська, Одеська, Чернігівська область | E11: 00497360 | F11: Чернігівська область | G11: Аграрно-ветеринарний | H11: 18.6678 | I11: 4.6297 | J11: 15.8602 | K11: 60.7505 | L11: 1.05 | M11: 1.22 | N11: 78 | O11: А | P11: Кількість молодих вчених П6, І3 | Q11: 4.8 | R11: 0.149 | S11: 1
A12: Інститут агроекології і природокористування Національної академії аграрних наук України | B12: Наукова установа | C12: Національна академія агрраних наук України | D12: інші області | E12: 13722478 | F12: Київ | G12: Аграрно-ветеринарний | H12: 22.4295 | I12: 4.6333 | J12: 18.8703 | K12: 72.2803 | L12: 1 | M12: 1 | N12: 72 | O12: Б | P12: Кількість молодих вчених П6, І3 | Q12: 17.4 | R12: 0.235 | S12: 1
A13: Державна установа Інститут зернових культур Національної академії аграрних наук України | B13: Наукова установа | C13: Національна академія агрраних наук України | D13: Дніпропетровська, Одеська, Чернігівська область | E13: 00496662 | F13: Дніпропетровська область | G13: Аграрно-ветеринарний | H13: 20.5148 | I13: 5.2083 | J13: 17.4535 | K13: 66.8535 | L13: 1.05 | M13: 1 | N13: 70 | O13: Б | P13: Кількість молодих вчених П6, І3 | Q13: 15.8 | R13: 0.148 | S13: 1
... A1982: Державний вищий навчальний заклад "Ужгородський національний університет" | B1982: Заклад вищої освіти | C1982: Міністерство освіти і науки України | D1982: інші області | E1982: 02070832 | F1982: Закарпатська область | G1982: Аграрно-ветеринарний | H1982: 5.3946 | I1982: 5 | J1982: 5.3157 | K1982: 13.2338 | L1982: 1 | M1982: 1 | N1982: 13 | O1982: Г | P1982: Кількість заявок на загальнодержавні гранти Р18, І33 | Q1982: 0 | R1982: 0 | S1982: 0

Sheet Аркуш19
A1: Сума вагових коєфіцієнтів, I* | B1: Середній бал Експерта
A2: 36.5469 | B2: 6.1
A3: 43.689 | B3: 7
A4: 36.794 | B4: 6.1333
A5: 30.0178 | B5: 5.9667
A6: 33.9394 | B6: 6.5187
A7: 32.7942 | B7: 7.4333
A8: 30.101 | B8: 5.3667
A9: 28.7447 | B9: 3.7
A10: 28.4164 | B10: 4.2667
A11: 29.9882 | B11: 4.4667
A12: 29.16 | B12: 5.9
A13: 28.9646 | B13: 4.4
... A229: 6.3266 | B229: 4.875
A230: - | B230: -
A231: - | B231: -
A232: 45.5843 | B232: 7.8
A233: 40.6713 | B233: 7.5667
A234: 44.1836 | B234: 7.4443
A235: 38.5483 | B235: 6.8667
A236: 37.187 | B236: 7.0667
A237: 42.2071 | B237: 6.0333
A238: 34.5673 | B238: 6
A239: 35.7692 | B239: 6.8
A240: 33.8829 | B240: 5.5333
A241: 35.3557 | B241: 5.5713
A242: 25.8006 | B242: 5.7
A243: 29.8018 | B243: 6.5557
... A513: 1.2446 | B513: 4.4443

Sheet Попередня підготовка
A1: Назва Установи / Середньорічні показники | B1: Напрям | C1: Установа | D1: Підпорядкування | E1: Регіон | F1: ЄДРПОУ | G1: Область | H1: Сума вагових коєфіцієнтів, I* | I1: Середній бал Експерта | J1: Зважена сумарна оцінка (80/20) | K1: Нормована зважена сумарна оцінка | L1: Регіональний коєфіцієнт | M1: Коєфіцієнт руйнувань | N1: Попередня атестаційна оцінка | O1: Група
A2: Київський національний університет імені Тараса Шевченка | B2: Природничо-математичний | C2: Заклад вищої освіти | D2: Міністерство освіти і науки України | E2: інші області | F2: 02070944 | G2: Київ | H2: 45.5843 | I2: 7.8 | J2: 38.0274 | K2: 100 | L2: 1 | M2: 1.034 | N2: 100 | O2: А
A3: Харківський національний університет імені В.Н. Каразіна | B3: Природничо-математичний | C3: Заклад вищої освіти | D3: Міністерство освіти і науки України | E3: Донецька, Запорізька, Луганська, Миколаївська, Сумська, Харківська, Херсонська область | F3: 02071205 | G3: Харківська область | H3: 40.6713 | I3: 7.5667 | J3: 34.0504 | K3: 89.5418 | L3: 1.1 | M3: 1.092 | N3: 100 | O3: А
A4: Національний університет «Львівська політехніка» | B4: Природничо-математичний | C4: Заклад вищої освіти | D4: Міністерство освіти і науки України | E4: інші області | F4: 02071010 | G4: Львівська область | H4: 44.1836 | I4: 7.4443 | J4: 36.8357 | K4: 96.8662 | L4: 1 | M4: 1 | N4: 97 | O4: А
A5: Сумський державний університет | B5: Природничо-математичний | C5: Заклад вищої освіти | D5: Міністерство освіти і науки України | E5: Донецька, Запорізька, Луганська, Миколаївська, Сумська, Харківська, Херсонська область | F5: 05408289 | G5: Сумська область | H5: 38.5483 | I5: 6.8667 | J5: 32.212 | K5: 84.7073 | L5: 1.1 | M5: 1.004 | N5: 94 | O5: А
A6: Національний технічний університет "Харківський політехнічний інститут" | B6: Природничо-математичний | C6: Заклад вищої освіти | D6: Міністерство освіти і науки України | E6: Донецька, Запорізька, Луганська, Миколаївська, Сумська, Харківська, Херсонська область | F6: 02071180 | G6: Харківська область | H6: 37.187 | I6: 7.0667 | J6: 31.1629 | K6: 81.9485 | L6: 1.1 | M6: 1.028 | N6: 93 | O6: А
A7: Державний вищий навчальний заклад "Ужгородський національний університет" | B7: Природничо-математичний | C7: Заклад вищої освіти | D7: Міністерство освіти і науки України | E7: інші області | F7: 02070832 | G7: Закарпатська область | H7: 42.2071 | I7: 6.0333 | J7: 34.9723 | K7: 91.9661 | L7: 1 | M7: 1 | N7: 92 | O7: А
A8: Харківський національний університет міського господарства імені О.М.Бекетова | B8: Природничо-математичний | C8: Заклад вищої освіти | D8: Міністерство освіти і науки України | E8: Донецька, Запорізька, Луганська, Миколаївська, Сумська, Харківська, Херсонська область | F8: 02071151 | G8: Харківська область | H8: 34.5673 | I8: 6 | J8: 28.8538 | K8: 75.8763 | L8: 1.1 | M8: 1.023 | N8: 85 | O8: А
A9: Львівський національний університет імені Івана Франка | B9: Природничо-математичний | C9: Заклад вищої освіти | D9: Міністерство освіти і науки України | E9: інші області | F9: 02070987 | G9: Львівська область | H9: 35.7692 | I9: 6.8 | J9: 29.9754 | K9: 78.8258 | L9: 1 | M9: 1 | N9: 79 | O9: А
A10: Дніпровський національний університет імені Олеся Гончара | B10: Природничо-математичний | C10: Заклад вищої освіти | D10: Міністерство освіти і науки України | E10: Дніпропетровська, Одеська, Чернігівська область | F10: 02066747 | G10: Дніпропетровська область | H10: 33.8829 | I10: 5.5333 | J10: 28.213 | K10: 74.1912 | L10: 1.05 | M10: 1 | N10: 78 | O10: А
A11: Прикарпатський національний університет імені Василя Стефаника | B11: Природничо-математичний | C11: Заклад вищої освіти | D11: Міністерство освіти і науки України | E11: інші області | F11: 02125266 | G11: Івано-Франківська область | H11: 35.3557 | I11: 5.5713 | J11: 29.3988 | K11: 77.3095 | L11: 1 | M11: 1 | N11: 77 | O11: А
A12: Запорізький національний університет | B12: Природничо-математичний | C12: Заклад вищої освіти | D12: Міністерство освіти і науки України | E12: Донецька, Запорізька, Луганська, Миколаївська, Сумська, Харківська, Херсонська область | F12: 02125243 | G12: Запорізька область | H12: 25.8006 | I12: 5.7 | J12: 21.7805 | K12: 57.2758 | L12: 1.1 | M12: 1.157 | N12: 73 | O12: Б
A13: Національний технічний університет «Дніпровська політехніка» | B13: Природничо-математичний | C13: Заклад вищої освіти | D13: Міністерство освіти і науки України | E13: Дніпропетровська, Одеська, Чернігівська область | F13: 02070743 | G13: Дніпропетровська область | H13: 29.8018 | I13: 6.5557 | J13: 25.1526 | K13: 66.1434 | L13: 1.05 | M13: 1 | N13: 69 | O13: Б
... A283: ДЕРЖАВНЕ ПІДПРИЄМСТВО "ДНІПРОПЕТРОВСЬКИЙ РЕГІОНАЛЬНИЙ ДЕРЖАВНИЙ НАУКОВО-ТЕХНІЧНИЙ ЦЕНТР СТАНДАРТИЗАЦІЇ,МЕТРОЛОГІЇ ТА СЕРТИФІКАЦІЇ" | B283: Інженерно-технологічний | C283: Наукова установа | D283: Міністерство економіки України | E283: Дніпропетровська, Одеська, Чернігівська область | F283: 04725947 | G283: Дніпропетровська область | H283: 1.2446 | I283: 4.4443 | J283: 1.8845 | K283: 5.8466 | L283: 1.05 | M283: 1 | N283: 6 | O283: Г

Sheet Установи та підпорядкування
A1: № | B1: Найменування наукової установи / закладу вищої освіти* | C1: Підпорядкування | D1: Регіон | E1: ЄДРПОУ | F1: Область | G1: Відповідальні особи вказаної установи | H1: Підпорядкованість | I1: Місцезнаходження* | J1: Ідентифікаційний код за ЄДРПОУ* | K1: Регіон розташування НУ / ЗВО
A2: 3106 | B2: Приватне акціонерне товариство "Елемент" | C2: - | D2: Дніпропетровська, Одеська, Чернігівська область | E2: 30863766 | F2: Одеська область | G2: Ранченко Геннадій Степанович | H2: - | I2: 65078, м.Одеса, вул. Героїв Крут, 27 | J2: Одеська область | P2: Область
A3: 53 | B3: Державне підприємство "Український науково-дослідний інститут радіо і телебачення" | C3: Адміністрація Державної служби спеціального зв'язку та захисту інформації України | D3: інші області | E3: 01181535 | F3: Одеська область | G3: Бедрій Дмитро Іванович | H3: Адміністрація Державної служби спеціального зв'язку та захисту інформації України | I3: 65026, ОДЕСЬКА ОБЛ., ОДЕСЬКИЙ РАЙОН, МІСТО ОДЕСА, ПРИМОРСЬКИЙ РАЙОН, ВУЛ. БУНІНА, БУДИНОК 31 | J3: Одеська область | P3: Одеська область | R3: {=Sort(UNIQUE(P:P))} -> Вінницька область
A4: 6629 | B4: ПРАТ “Український інститут із проектування і розвитку інформаційно-комунікаційної інфраструктури «ДІПРОЗВ‘ЯЗОК» | C4: Адміністрація Державної служби спеціального зв'язку та захисту інформації України | D4: інші області | E4: 01168185 | F4: Київ | G4: Бридковська Вікторія Миколаївна | H4: Адміністрація Державної служби спеціального зв'язку та захисту інформації України | I4: вул. Солом'янська, 3, Київ, 03110 | J4: Київ | P4: Одеська область | R4: Волинська область
A5: 3103 | B5: Науково-дослідний, проектно-конструкторський та технологічний інститут мікрографії | C5: Державна архівна служба України | D5: Донецька, Запорізька, Луганська, Миколаївська, Сумська, Харківська, Херсонська область | E5: 14321156 | F5: Харківська область | G5: Виноградова Ольга Євгеніївна | H5: Державна архівна служба України | I5: 61157, м. Харків, вул. Москалівська, 139 | J5: Харківська область | P5: Київ | R5: Дніпропетровська область
A6: 3131 | B6: Державне підприємство "Державний науково-технічний центр з ядерної та радіаційної безпеки" | C6: Державна інспекція ядерного регулювання України та Відділення енергетики та енергетичних технологій Національної академії наук України | D6: інші області | E6: 14282338 | F6: Київ | G6: Андрюшко Юлія Володимирівна | H6: Державна інспекція ядерного регулювання України та Відділення енергетики та енергетичних технологій Національної академії наук України | I6: 03142, вул. Василя Стуса 35-37, Київ, Україна | J6: Київ | P6: Харківська область | R6: Донецька область
A7: 4189 | B7: УКРАЇНСЬКИЙ ГІДРОМЕТЕОРОЛОГІЧНИЙ ІНСТИТУТ ДЕРЖАВНОЇ СЛУЖБИ УКРАЇНИ З НАДЗВИЧАЙНИХ СИТУАЦІЙ ТА НАЦІОНАЛЬНОЇ АКАДЕМІЇ НАУК УКРАЇНИ | C7: Державна служба України з надзвичайних ситуацій та Національна академія наук України | D7: інші області | E7: 02572508 | F7: Київ | G7: Мостова Ніна Михайлівна | H7: Державна служба України з надзвичайних ситуацій та Національна академія наук України | I7: Київ, проспект Науки, 37 | J7: Київ | P7: Київ | R7: Житомирська область
A8: 3043 | B8: ДЕРЖАВНЕ ПІДПРИЄМСТВО "НАЦІОНАЛЬНИЙ ІНСТИТУТ РОЗВИТКУ ІНФРАСТРУКТУРИ" | C8: Державне агентство відновлення та розвитку інфраструктури України | D8: інші області | E8: 03450778 | F8: Київ | G8: Каськів Володимир Іванович | H8: Державне агентство відновлення та розвитку інфраструктури України | I8: 00113, Київ, просп. Берестейський, буд. 57 | J8: Київ | P8: Київ | R8: Закарпатська область
A9: 6079 | B9: Чорнобильський радіаційно-екологічний біосферний заповідник | C9: Державне агентство України з управління зоною відчуження | D9: інші області | E9: 41246328 | F9: Київська область | G9: Симоненко Олександр Григорович | H9: Державне агентство України з управління зоною відчуження | I9: 07201, Київська область, Вишгородський район, смт Іванків, вулиця Толочина, будинок 28 | J9: Київська область | P9: Київ | R9: Запорізька область
A10: 3132 | B10: ДЕРЖАВНЕ ПІДПРИЄМСТВО КОНСТРУКТОРСЬКЕ БЮРО ПІВДЕННЕ ІМ. М.К.ЯНГЕЛЯ | C10: Державне космічне агентство України | D10: Дніпропетровська, Одеська, Чернігівська область | E10: 14308304 | F10: Дніпропетровська область | G10: Коляда Олена Олександрівна | H10: Державне космічне агентство України | I10: м.Дніпро, вул. Криворізька, 3 | J10: Дніпропетровська область | P10: Київська область | R10: Івано-Франківська область
A11: 1866 | B11: Харківський національний університет Повітряних Сил імені Івана Кожедуба | C11: Командування Повітряних Сил Збройних Сил України | D11: Донецька, Запорізька, Луганська, Миколаївська, Сумська, Харківська, Херсонська область | E11: 24980799 | F11: Харківська область | G11: Гурін Артем Петрович | H11: Командування Повітряних Сил Збройних Сил України | I11: м. Харків, вул. Сумська, 77/79, 61023 | J11: Харківська область | P11: Дніпропетровська область | R11: Київ
A12: 3042 | B12: НАУКОВО-ДОСЛІДНА УСТАНОВА "УКРАЇНСЬКИЙ НАУКОВО-ДОСЛІДНИЙ ІНСТИТУТ ЕКОЛОГІЧНИХ ПРОБЛЕМ" | C12: Мінистерство захисту довкілля та природних ресурсів України | D12: Донецька, Запорізька, Луганська, Миколаївська, Сумська, Харківська, Херсонська область | E12: 01018083 | F12: Харківська область | G12: Дербіна Оксана Іванівна | H12: Мінистерство захисту довкілля та природних ресурсів України | I12: м. Харків, вул. Єніна Євгенія, 6, 61165 | J12: Харківська область | P12: Харківська область | R12: Київська область
A13: 5909 | B13: ВСЕУКРАЇНСЬКИЙ ДЕРЖАВНИЙ НАУКОВО-ВИРОБНИЧИЙ ЦЕНТР СТАНДАРТИЗАЦІЇ, МЕТРОЛОГІЇ, СЕРТИФІКАЦІЇ ТА ЗАХИСТУ ПРАВ СПОЖИВАЧІВ | C13: Міністерство економіки України | D13: інші області | E13: 02568182 | F13: Київ | G13: Полікарпов Олексій Олександрович | H13: Міністерство економіки України | I13: 03143, Київ, вул. Метрологічна, 4 | J13: Київ | P13: Харківська область | R13: Кіровоградська область
A14: 6621 | B14: ДЕРЖАВНЕ ПІДПРИЄМСТВО "ДНІПРОПЕТРОВСЬКИЙ РЕГІОНАЛЬНИЙ ДЕРЖАВНИЙ НАУКОВО-ТЕХНІЧНИЙ ЦЕНТР СТАНДАРТИЗАЦІЇ,МЕТРОЛОГІЇ ТА СЕРТИФІКАЦІЇ" | C14: Міністерство економіки України | D14: Дніпропетровська, Одеська, Чернігівська область | E14: 04725947 | F14: Дніпропетровська область | G14: Скріпнік Марина Анатоліївна | H14: Міністерство економіки України | I14: ВУЛ. БАРИКАДНА, 23, М. ДНІПРО, ДНІПРОПЕТРОВСЬКА ОБЛ., УКРАЇНА, 49044 | J14: Дніпропетровська область | P14: Київ | R14: Крим
A15: 7035 | B15: ДЕРЖАВНЕ ПІДПРИЄМСТВО ІВАНО-ФРАНКІВСЬКИЙ НАУКОВО-ВИРОБНИЧИЙ ЦЕНТР СТАНДАРТИЗАЦІЇ, МЕТРОЛОГІЇ ТА СЕРТИФІКАЦІЇ | C15: Міністерство економіки України | D15: інші області | E15: 02568176 | F15: Івано-Франківська область | G15: Бас Олександр Анатолійович | H15: Міністерство економіки України | I15: вул. Вовчинецька, 127, м. Івано-Франківськ, Україна, 76007 | J15: Івано-Франківська область | P15: Дніпропетровська область | R15: Луганська область
... A31: 3278 | B31: Кременчуцький національний університет імені Михайла Остроградського | C31: Міністерство освіти і науки України | D31: інші області | E31: 05385631 | F31: Полтавська область | G31: Латишева Вікторія Володимирівна | H31: Міністерство освіти і науки України | I31: вул. Першотравнева, 20, м. Кременчук | J31: Полтавська область | P31: Хмельницька область | R31: Чернігівська область
A32: 3369 | B32: Національний аерокосмічний університет ім. М. Є. Жуковського «Харківський авіаційний інститут» | C32: Міністерство освіти і науки України | D32: Донецька, Запорізька, Луганська, Миколаївська, Сумська, Харківська, Херсонська область | E32: 02066769 | F32: Харківська область | G32: Гуменний Андрій Михайлович | H32: Міністерство освіти і науки України | I32: 61070, вул. Вадима Манька (колишня Чкалова), 17, м. Харків, Україна | J32: Харківська область | P32: Полтавська область
A33: 257 | B33: Національний технічний університет "Харківський політехнічний інститут" | C33: Міністерство освіти і науки України | D33: Донецька, Запорізька, Луганська, Миколаївська, Сумська, Харківська, Херсонська область | E33: 02071180 | F33: Харківська область | G33: Варакута Микита Володимирович | H33: Міністерство освіти і науки України | I33: Україна, 61002, м. Харків, вул. Кирпичова, 2 | J33: Харківська область | P33: Харківська область
A34: 3666 | B34: Національний університет "Чернігівський колегіум" імені Т.Г. Шевченка | C34: Міністерство освіти і науки України | D34: Дніпропетровська, Одеська, Чернігівська область | E34: 02125674 | F34: Чернігівська область | G34: Руднік Інна Володимирівна | H34: Міністерство освіти і науки України | I34: місто Чернігів | J34: Чернігівська область | P34: Харківська область
A35: 5840 | B35: Національний університет кораблебудування імені адмірала Макарова | C35: Міністерство освіти і науки України | D35: Донецька, Запорізька, Луганська, Миколаївська, Сумська, Харківська, Херсонська область | E35: 02066753 | F35: Миколаївська область | G35: Савенков Олег Ігорович | H35: Міністерство освіти і науки України | I35: м. Миколаїв, проспект Героїв України, 9 | J35: Миколаївська область | P35: Чернігівська область
A36: 5390 | B36: Природний заповідник «Розточчя» | C36: Міністерство освіти і науки України | D36: інші області | E36: 25232390 | F36: Львівська область | G36: Струс Юрій Михайлович | H36: Міністерство освіти і науки України | I36: вул. Січових Стрільців, 7, сщ. Івано-Франкове, Яворівського району, Львівської області 81070 | J36: Львівська область | P36: Миколаївська область
A37: 6602 | B37: Український державний університет науки і технологій | C37: Міністерство освіти і науки України | D37: Дніпропетровська, Одеська, Чернігівська область | E37: 44165850 | F37: Дніпропетровська область | G37: Ляховецька-Токарєва Марина Марківна | H37: Міністерство освіти і науки України | I37: вул. Лазаряна, 2, м. Дніпро, 49010, Україна | J37: Дніпропетровська область | P37: Львівська область
A38: 3238 | B38: Харківський національний університет міського господарства імені О.М.Бекетова | C38: Міністерство освіти і науки України | D38: Донецька, Запорізька, Луганська, Миколаївська, Сумська, Харківська, Херсонська область | E38: 02071151 | F38: Харківська область | G38: Сухонос Марія Костянтинівна | H38: Міністерство освіти і науки України | I38: 61002, Харківська область, місто Харків, вул. Чорноглазівська, 17 | J38: Харківська область | P38: Дніпропетровська область
A39: 3276 | B39: Харківський національний університет радіоелектроніки | C39: Міністерство освіти і науки України | D39: Донецька, Запорізька, Луганська, Миколаївська, Сумська, Харківська, Херсонська область | E39: 02071197 | F39: Харківська область | G39: Добренюк Максим Миколайович | H39: Міністерство освіти і науки України | I39: пр. Науки, 14, м. Харків, 61166, Україна | J39: Харківська область | P39: Харківська область
A40: 4003 | B40: НАВЧАЛЬНО-НАУКОВИЙ КОМПЛЕКС "ІНСТИТУТ ПРИКЛАДНОГО СИСТЕМНОГО АНАЛІЗУ" НАЦІОНАЛЬНОГО ТЕХНІЧНОГО УНІВЕРСИТЕТУ УКРАЇНИ "КИЇВСЬКИЙ ПОЛІТЕХНІЧНИЙ ІНСТИТУТ ІМЕНІ ІГОРЯ СІКОРСЬКОГО" | C40: Міністерство освіти і науки України та Національна академія наук України | D40: інші області | E40: 25408067 | F40: Київ | G40: Палійчук Лілія Сергіївна | H40: Міністерство освіти і науки України та Національна академія наук України | I40: 03056, Київ, проспект Перемоги (Берестейський) 37, корпус 35 | J40: Київ | P40: Харківська область
A41: 6070 | B41: Національний центр "Мала академія наук України" | C41: Міністерство освіти і науки України та Національна академія наук України | D41: інші області | E41: 32827468 | F41: Київ | G41: Ємець Вікторія Василівна | H41: Міністерство освіти і науки України та Національна академія наук України | I41: 01021, Київ, Кловський узвіз 8; 04119, Київ, вул. Дегтярівська, 38/44 | J41: Київ | P41: Київ
A42: 6854 | B42: Державне підприємство "Державний автотранспортний науково-дослідний і проектний інститут" | C42: Міністерство розвитку громад та територій України | D42: інші області | E42: 01527695 | F42: Київ | G42: Тарабан Сергій Миколайович | H42: Міністерство розвитку громад та територій України | I42: просп. Берестейський, 57, Київ, 03113 | J42: Київ | P42: Київ
A43: 7349 | B43: Державне підприємство "Державний науково-дослідний інститут будівельних конструкцій" | C43: Міністерство розвитку громад та територій України | D43: інші області | E43: 02495431 | F43: Київ | G43: Гах Наталія Дмитріївна | H43: Міністерство розвитку громад та територій України | I43: вул. Преображенська, 5/2, Київ, 03037 | J43: Київ | P43: Київ
... A163: 3041 | B163: Державне підприємство "Український державний науково-дослідний вуглехімічний інститут" | C163: Фонд державного майна України | D163: Донецька, Запорізька, Луганська, Миколаївська, Сумська, Харківська, Херсонська область | E163: 00190443 | F163: Харківська область | G163: Коваль Валентин Валерійович | H163: Фонд державного майна України | I163: 61023, вул. Весніна, 7, м. Харків, Харківська обл., Україна | J163: Харківська область | P163: Полтавська область
A164: 76 | B164: Бердянський державний педагогічний університет | C164: Міністерство освіти і науки України | D164: тимчасово переміщений НУ / ЗВО, що утримує матеріально-технічну базу за своєю юридичною адресою | E164: 02125220 | F164: Запорізька область | G164: Кізілова Дар'я Олександрівна | P164: Харківська область
A165: 113 | B165: Вінницький державний педагогічний університет імені Михайла Коцюбинського | C165: Міністерство освіти і науки України | D165: інші області | E165: 02125094 | F165: Вінницька область | G165: Бак Сергій Миколайович | P165: Запорізька область
A166: 46 | B166: Вінницький національний аграрний університет | C166: Міністерство освіти і науки України | D166: інші області | E166: 00497236 | F166: Вінницька область | G166: Разанова Олена Петрівна | P166: Вінницька область
A167: 24 | B167: Волинський національний університет імені Лесі Українки | C167: Міністерство освіти і науки України | D167: інші області | E167: 02125102 | F167: Волинська область | G167: Мельничук Христина Олегівна | P167: Вінницька область
A168: 1028 | B168: ДВНЗ «Донбаський державний педагогічний університет» | C168: Міністерство освіти і науки України | D168: тимчасово переміщений НУ / ЗВО, що утримує матеріально-технічну базу за своєю юридичною адресою | E168: 38177113 | F168: Донецька область | G168: Ольховська Юлія Дмитрівна | P168: Волинська область
A169: 730 | B169: ДВНЗ «Донецький національний технічний університет» | C169: Міністерство освіти і науки України | D169: тимчасово переміщений НУ / ЗВО, що утримує матеріально-технічну базу за своєю юридичною адресою | E169: 02070826 | F169: Донецька область | G169: Алтухова Тетяна Володимирівна | P169: Донецька область
A170: 78 | B170: Державне некомерційне підприємство "Державний Університет "Київський авіаційний інститут" | C170: Міністерство освіти і науки України | D170: інші області | E170: 45853942 | F170: Київ | G170: Рибалко Олена Леонідівна | P170: Донецька область
A171: 11 | B171: Державний вищий навчальний заклад "Ужгородський національний університет" | C171: Міністерство освіти і науки України | D171: інші області | E171: 02070832 | F171: Закарпатська область | G171: Лукач Ольга Іванівна | P171: Київ
A172: 900 | B172: Державний вищий навчальний заклад «Приазовський державний технічний університет» | C172: Міністерство освіти і науки України | D172: тимчасово переміщений НУ / ЗВО, що утримує матеріально-технічну базу за своєю юридичною адресою | E172: 02070812 | F172: Донецька область | G172: Шишкін Володимир Вікторович | P172: Закарпатська область
A173: 21 | B173: Державний заклад "Луганський національний університет імені Тараса Шевченка" | C173: Міністерство освіти і науки України | D173: тимчасово переміщений НУ / ЗВО, що утримує матеріально-технічну базу за своєю юридичною адресою | E173: 02125131 | F173: Луганська область | G173: Вовк Світлана Олександрівна | P173: Донецька область
A174: 13 | B174: Державний заклад "Південноукраїнський національний педагогічний університет імені К. Д. Ушинського" | C174: Міністерство освіти і науки України | D174: Дніпропетровська, Одеська, Чернігівська область | E174: 02125473 | F174: Одеська область | G174: Бєлітченко Дмитро Миколайович | P174: Луганська область
...

Sheet Динаміка
